Workbook
Name Customer_ID: #REF!
Name Month: #REF!
Name raphic5: #REF!
Name Slicer_AGENCY: #N/A
Name Slicer_PROJECT_NAME: #N/A

Sheet ChartsDataSheet
A1: Gauge Chart Name: | B1: AV | C1: 1 | D1: 2 | E1: 3 | F1: min | G1: max | H1: diff | I1: Format | J1: Decimals | K1: Labels size | L1: AV size | M1: ref 2E | N1: ref 1E | O1: color 1 | P1: color 2 | Q1: color 3 | R1: Skin | S1: Sheet Name | T1: Sheet Index | U1: Attached | V1: Reference | W1: color AV | X1: Description | Y1: Size | Z1: PV | AA1: 1 | AB1: 2 | AC1: 3 | AD1: min | AE1: max | AF1: diff | AG1: TextBoxDiff | AH1: color PV | AI1: ref 4S | AJ1: ref 4E | AK1: ref 5E | AL1: ref 6E | AM1: ref 7E | AN1: ref 8E | AO1: ref 9E | AP1: ref 10E | AQ1: ref 11E | AR1: ref 12E | AS1: color 4 | AT1: color 5 | AU1: color 6 | AV1: color 7 | AW1: color 8 | AX1: color 9 | AY1: color 10 | AZ1: color 11 | BA1: color 12 | BB1: Zones Count | BC1: Hform | BD1: Reverse? | BE1: 1 | BF1: 2 | BG1: 3 | BH1: 1 | BI1: 2 | BJ1: 3 | BK1: color LB | BL1: color A | BM1: color D | CW1: Variance Chart Name: | CX1: Sheet Name | CY1: Sheet Index | CZ1: Attached | DA1: Reference | DB1: Data 1 | DC1: Data 2 | DD1: Diff | DE1: Series 1 | DF1: Series 2 | DG1: Data 1 | DH1: Data 2 | DI1: Diff | DJ1: Series 1 | DK1: Series 2 | BES1: Sales Funnel Chart Name: | BET1: Sheet Name | BEU1: Sheet Index | BEV1: Attached | BEW1: Reference | BEX1: Series 1 | BIO1: TL Chart Name: | BIP1: AV | BIQ1: Green | BIR1: Yellow | BIS1: AV Val. | BIT1: Size 1 | BIU1: Size 2 | BIV1: Size 3 | BIW1: Format | BIX1: Decimals | BIY1: ForeColor | BIZ1: Border | BJA1: Off Light | BJB1: Text | BJC1: Color 1 | BJD1: Color 2 | BJE1: Color 3 | BJF1: Model | BJG1: Sheet Name | BJH1: Sheet Index | BJI1: Attached | BJJ1: Reference | BJK1: Minim | BJL1: Maxim | BUC1: VarianceActualHorizontal: | BUD1: Sheet Name | BUE1: Sheet Index | BUF1: Attached | BUG1: Reference | BXY1: WaterFallChart Name: | BXZ1: Sheet Name | BYA1: Sheet Index | BYB1: Attached | BYC1: Reference | BYD1: Labels | BYE1: Values | BYF1: Cumulative | BYG1: Start - End | BYH1: Before | BYI1: After | BYJ1: Data label position | CBU1: MekkoChart Name: | CBV1: Sheet Name | CBW1: Sheet Index | CBX1: Attached | CBY1: Reference | CFQ1: OrgChart Name: | CFR1: Sheet Name | CFS1: Sheet Index | CFT1: Attached | CFU1: Reference | CJM1: RadialBarChart Name: | CJN1: Sheet Name | CJO1: Sheet Index | CJP1: Attached | CJQ1: Reference | CJR1: MaxValue | CJS1: Value 1 | CJT1: Desc 1 | CJU1: v 1 | CJV1: i 1 | CJW1: Value 2 | CJX1: Desc 2 | CJY1: v 2 | CJZ1: i 2 | CKA1: Value 3 | CKB1: Desc 3 | CKC1: v 3 | CKD1: i 3 | CKE1: Value 4 | CKF1: Desc 4 | CKG1: v 4 | CKH1: i 4 | CKI1: Value 5 | CKJ1: Desc 5 | CKK1: v 5 | CKL1: i 5 | CKM1: Value 6 | CKN1: Desc 6 | CKO1: v 6 | CKP1: i 6 | CKQ1: Value 7 | CKR1: Desc 7 | CKS1: v 7 | CKT1: i 7 | CKU1: Value 8 | CKV1: Desc 8 | CKW1: v 8 | CKX1: i 8 | CKY1: Value 9 | CKZ1: Desc 9 | CLA1: v 9 | CLB1: i 9 | CLC1: Value 10 | CLD1: Desc 10 | CLE1: v 10 | CLF1: i 10 | CNI1: Sales Funnel2 Chart Name: | CNJ1: Sheet Name | CNK1: Sheet Index | CNL1: Attached | CNM1: Reference | CNN1: Colors | CNO1: DataText | CNP1: DataValue | CNQ1: x | CNR1: Label | CNS1: Value | CNT1: Low | CNU1: High | CNV1: x2 | CNW1: yLabel | CNX1: yPercent | CNY1: LabelPercent | CNZ1: xxx | COA1: xxx | COB1: xxx | CRE1: Ring Chart Name: | CRF1: Sheet Name | CRG1: Sheet Index | CRH1: Attached | CRI1: Reference | CRJ1: Value 1 | CRK1: Value 2 | CRL1: Color 1 | CRM1: Color 2 | CVA1: WindRoseChart Name: | CVB1: Sheet Name | CVC1: Sheet Index | CVD1: Attached | CVE1: Reference | CVF1: Cat 1 | CVG1: Cat 2 | CVH1: Cat 3 | CVI1: Cat 4 | CVJ1: Cat 5 | CVK1: Cat 6
CNI2: SF2_1 | CNJ2: =SUBSTITUTE(MID(_xlfn.FORMULATEXT(CNM2),2,FIND("!",_xlfn.FORMULATEXT(CNM2),1)-2), "'","") -> New Sankey | CNK2: =_xlfn.SHEET( 'New Sankey'!$NTP$1000000) -> 5 | CNM2: ='New Sankey'!$NTP$1000000 -> 0 | CNQ2: 1 | CNS2: =CNP3 -> 2723028.5 | CNT2: 0 | CNU2: =CNS2/2+CNS2/2 -> 2723028.5 | CNW2: =(CNU2/2)-(CNU2/2)*6/100 -> 1279823.4 | CNX2: =(CNU2/2)+(CNU2/2)*7/100 -> 1456820.2
CNI3: SF2_1 | CNJ3: =SUBSTITUTE(MID(_xlfn.FORMULATEXT(CNM3),2,FIND("!",_xlfn.FORMULATEXT(CNM3),1)-2), "'","") -> New Sankey | CNK3: =_xlfn.SHEET( 'New Sankey'!$NTP$1000000) -> 5 | CNM3: ='New Sankey'!$NTP$1000000 -> 0 | CNN3: 12345678 | CNO3: ='New Sankey'!$K$2 -> Aster PPK | CNP3: ='New Sankey'!$L$2 -> 2723028.5 | CNQ3: =CNQ2+1 -> 2 | CNR3: =CONCATENATE(CNO3," ",CNP3) -> Aster PPK 2723028.4668 | CNS3: =CNP3 -> 2723028.5 | CNT3: =CNS2/2-CNS3/2 -> 0 | CNU3: =CNS2/2+CNS3/2 -> 2723028.5 | CNV3: =CNQ2+1/2 -> 1.5 | CNW3: =CNW2 -> 1279823.4 | CNX3: =CNX2 -> 1456820.2 | CNY3: =CNS3/CNS2 -> 1
CNI4: SF2_1 | CNJ4: =SUBSTITUTE(MID(_xlfn.FORMULATEXT(CNM4),2,FIND("!",_xlfn.FORMULATEXT(CNM4),1)-2), "'","") -> New Sankey | CNK4: =_xlfn.SHEET( 'New Sankey'!$NTP$1000000) -> 5 | CNM4: ='New Sankey'!$NTP$1000000 -> 0 | CNN4: 12345678 | CNO4: ='New Sankey'!$K$3 -> Cantor Asia Media | CNP4: ='New Sankey'!$L$3 -> 1746051.4 | CNQ4: =CNQ3+1 -> 3 | CNR4: =CONCATENATE(CNO4," ",CNP4) -> Cantor Asia Media 1746051.3834 | CNS4: =CNP4 -> 1746051.4 | CNT4: =CNS2/2-CNS4/2 -> 488488.54 | CNU4: =CNS2/2+CNS4/2 -> 2234539.9 | CNV4: =CNQ3+1/2 -> 2.5 | CNW4: =CNW3 -> 1279823.4 | CNX4: =CNX3 -> 1456820.2 | CNY4: =CNS4/CNS2 -> 0.64121672
CNI5: SF2_1 | CNJ5: =SUBSTITUTE(MID(_xlfn.FORMULATEXT(CNM5),2,FIND("!",_xlfn.FORMULATEXT(CNM5),1)-2), "'","") -> New Sankey | CNK5: =_xlfn.SHEET( 'New Sankey'!$NTP$1000000) -> 5 | CNM5: ='New Sankey'!$NTP$1000000 -> 0 | CNN5: 12345678 | CNO5: ='New Sankey'!$K$4 -> Geoffrey Monty Allen | CNP5: ='New Sankey'!$L$4 -> 920570.16 | CNQ5: =CNQ4+1 -> 4 | CNR5: =CONCATENATE(CNO5," ",CNP5) -> Geoffrey Monty Allen 920570.1642 | CNS5: =CNP5 -> 920570.16 | CNT5: =CNS2/2-CNS5/2 -> 901229.15 | CNU5: =CNS2/2+CNS5/2 -> 1821799.3 | CNV5: =CNQ4+1/2 -> 3.5 | CNW5: =CNW4 -> 1279823.4 | CNX5: =CNX4 -> 1456820.2 | CNY5: =CNS5/CNS2 -> 0.33806851
CNI6: SF2_1 | CNJ6: =SUBSTITUTE(MID(_xlfn.FORMULATEXT(CNM6),2,FIND("!",_xlfn.FORMULATEXT(CNM6),1)-2), "'","") -> New Sankey | CNK6: =_xlfn.SHEET( 'New Sankey'!$NTP$1000000) -> 5 | CNM6: ='New Sankey'!$NTP$1000000 -> 0 | CNN6: 12345678 | CNO6: ='New Sankey'!$K$5 -> Idea Manufacturing | CNP6: ='New Sankey'!$L$5 -> 0 | CNQ6: =CNQ5+1 -> 5 | CNR6: =CONCATENATE(CNO6," ",CNP6) -> Idea Manufacturing 0 | CNS6: =CNP6 -> 0 | CNT6: =CNS2/2-CNS6/2 -> 1361514.2 | CNU6: =CNS2/2+CNS6/2 -> 1361514.2 | CNV6: =CNQ5+1/2 -> 4.5 | CNW6: =CNW5 -> 1279823.4 | CNX6: =CNX5 -> 1456820.2 | CNY6: =CNS6/CNS2 -> 0
CNI7: SF2_1 | CNJ7: =SUBSTITUTE(MID(_xlfn.FORMULATEXT(CNM7),2,FIND("!",_xlfn.FORMULATEXT(CNM7),1)-2), "'","") -> New Sankey | CNK7: =_xlfn.SHEET( 'New Sankey'!$NTP$1000000) -> 5 | CNM7: ='New Sankey'!$NTP$1000000 -> 0 | CNN7: 12345678 | CNO7: ='New Sankey'!$K$6 -> Korea SMB | CNP7: ='New Sankey'!$L$6 -> 1691093.3 | CNQ7: =CNQ6+1 -> 6 | CNR7: =CONCATENATE(CNO7," ",CNP7) -> Korea SMB 1691093.3245 | CNS7: =CNP7 -> 1691093.3 | CNT7: =CNS2/2-CNS7/2 -> 515967.57 | CNU7: =CNS2/2+CNS7/2 -> 2207060.9 | CNV7: =CNQ6+1/2 -> 5.5 | CNW7: =CNW6 -> 1279823.4 | CNX7: =CNX6 -> 1456820.2 | CNY7: =CNS7/CNS2 -> 0.62103402
CNI8: SF2_1 | CNJ8: =SUBSTITUTE(MID(_xlfn.FORMULATEXT(CNM8),2,FIND("!",_xlfn.FORMULATEXT(CNM8),1)-2), "'","") -> New Sankey | CNK8: =_xlfn.SHEET( 'New Sankey'!$NTP$1000000) -> 5 | CNM8: ='New Sankey'!$NTP$1000000 -> 0 | CNN8: 12345678 | CNO8: ='New Sankey'!$K$7 -> Last Station Group | CNP8: ='New Sankey'!$L$7 -> 1378028.8 | CNQ8: =CNQ7+1 -> 7 | CNR8: =CONCATENATE(CNO8," ",CNP8) -> Last Station Group 1378028.8353 | CNS8: =CNP8 -> 1378028.8 | CNT8: =CNS2/2-CNS8/2 -> 672499.82 | CNU8: =CNS2/2+CNS8/2 -> 2050528.7 | CNV8: =CNQ7+1/2 -> 6.5 | CNW8: =CNW7 -> 1279823.4 | CNX8: =CNX7 -> 1456820.2 | CNY8: =CNS8/CNS2 -> 0.50606479
CNI9: SF2_1 | CNJ9: =SUBSTITUTE(MID(_xlfn.FORMULATEXT(CNM9),2,FIND("!",_xlfn.FORMULATEXT(CNM9),1)-2), "'","") -> New Sankey | CNK9: =_xlfn.SHEET( 'New Sankey'!$NTP$1000000) -> 5 | CNM9: ='New Sankey'!$NTP$1000000 -> 0 | CNN9: 12345678 | CNO9: ='New Sankey'!$K$8 -> Top Notch Creative | CNP9: ='New Sankey'!$L$8 -> 1943021.8 | CNQ9: =CNQ8+1 -> 8 | CNR9: =CONCATENATE(CNO9," ",CNP9) -> Top Notch Creative 1943021.7769 | CNS9: =CNP9 -> 1943021.8 | CNT9: =CNS2/2-CNS9/2 -> 390003.34 | CNU9: =CNS2/2+CNS9/2 -> 2333025.1 | CNV9: =CNQ8+1/2 -> 7.5 | CNW9: =CNW8 -> 1279823.4 | CNX9: =CNX8 -> 1456820.2 | CNY9: =CNS9/CNS2 -> 0.71355177
CNI10: SF2_1 | CNJ10: =SUBSTITUTE(MID(_xlfn.FORMULATEXT(CNM10),2,FIND("!",_xlfn.FORMULATEXT(CNM10),1)-2), "'","") -> New Sankey | CNK10: =_xlfn.SHEET( 'New Sankey'!$NTP$1000000) -> 5 | CNM10: ='New Sankey'!$NTP$1000000 -> 0 | CNO10: BUBBLE | CNQ10: =CNQ9+31/100 -> 8.31 | CNR10: =CNS9 -> 1943021.8 | CNS10: =CNS2/2 -> 1361514.2
CNI11: SF2_2 | CNJ11: =SUBSTITUTE(MID(_xlfn.FORMULATEXT(CNM11),2,FIND("!",_xlfn.FORMULATEXT(CNM11),1)-2), "'","") -> New Sankey | CNK11: =_xlfn.SHEET( 'New Sankey'!$NTP$1000000) -> 5 | CNM11: ='New Sankey'!$NTP$1000000 -> 0 | CNQ11: 1 | CNS11: =CNP12 -> 10000 | CNT11: 0 | CNU11: =CNS11/2+CNS11/2 -> 10000 | CNW11: =(CNU11/2)-(CNU11/2)*6/100 -> 4700 | CNX11: =(CNU11/2)+(CNU11/2)*7/100 -> 5350
CNI12: SF2_2 | CNJ12: =SUBSTITUTE(MID(_xlfn.FORMULATEXT(CNM12),2,FIND("!",_xlfn.FORMULATEXT(CNM12),1)-2), "'","") -> New Sankey | CNK12: =_xlfn.SHEET( 'New Sankey'!$NTP$1000000) -> 5 | CNM12: ='New Sankey'!$NTP$1000000 -> 0 | CNN12: 12345678 | CNO12: ='New Sankey'!$H$18 -> All Work | CNP12: ='New Sankey'!$I$18 -> 10000 | CNQ12: =CNQ11+1 -> 2 | CNR12: =CONCATENATE(CNO12," ",CNP12) -> All Work 10000 | CNS12: =CNP12 -> 10000 | CNT12: =CNS11/2-CNS12/2 -> 0 | CNU12: =CNS11/2+CNS12/2 -> 10000 | CNV12: =CNQ11+1/2 -> 1.5 | CNW12: =CNW11 -> 4700 | CNX12: =CNX11 -> 5350 | CNY12: =CNS12/CNS11 -> 1
CNI13: SF2_2 | CNJ13: =SUBSTITUTE(MID(_xlfn.FORMULATEXT(CNM13),2,FIND("!",_xlfn.FORMULATEXT(CNM13),1)-2), "'","") -> New Sankey | CNK13: =_xlfn.SHEET( 'New Sankey'!$NTP$1000000) -> 5 | CNM13: ='New Sankey'!$NTP$1000000 -> 0 | CNN13: 12345678 | CNO13: ='New Sankey'!$H$19 -> Awarded | CNP13: ='New Sankey'!$I$19 -> 3000 | CNQ13: =CNQ12+1 -> 3 | CNR13: =CONCATENATE(CNO13," ",CNP13) -> Awarded 3000 | CNS13: =CNP13 -> 3000 | CNT13: =CNS11/2-CNS13/2 -> 3500 | CNU13: =CNS11/2+CNS13/2 -> 6500 | CNV13: =CNQ12+1/2 -> 2.5 | CNW13: =CNW12 -> 4700 | CNX13: =CNX12 -> 5350 | CNY13: =CNS13/CNS11 -> 0.3
CNI14: SF2_2 | CNJ14: =SUBSTITUTE(MID(_xlfn.FORMULATEXT(CNM14),2,FIND("!",_xlfn.FORMULATEXT(CNM14),1)-2), "'","") -> New Sankey | CNK14: =_xlfn.SHEET( 'New Sankey'!$NTP$1000000) -> 5 | CNM14: ='New Sankey'!$NTP$1000000 -> 0 | CNN14: 12345678 | CNO14: ='New Sankey'!$H$20 -> Women | CNP14: ='New Sankey'!$I$20 -> 254 | CNQ14: =CNQ13+1 -> 4 | CNR14: =CONCATENATE(CNO14," ",CNP14) -> Women 254 | CNS14: =CNP14 -> 254 | CNT14: =CNS11/2-CNS14/2 -> 4873 | CNU14: =CNS11/2+CNS14/2 -> 5127 | CNV14: =CNQ13+1/2 -> 3.5 | CNW14: =CNW13 -> 4700 | CNX14: =CNX13 -> 5350 | CNY14: =CNS14/CNS11 -> 0.0254
CNI15: SF2_2 | CNJ15: =SUBSTITUTE(MID(_xlfn.FORMULATEXT(CNM15),2,FIND("!",_xlfn.FORMULATEXT(CNM15),1)-2), "'","") -> New Sankey | CNK15: =_xlfn.SHEET( 'New Sankey'!$NTP$1000000) -> 5 | CNM15: ='New Sankey'!$NTP$1000000 -> 0 | CNO15: BUBBLE | CNQ15: =CNQ14+31/100 -> 4.31 | CNR15: =CNS14 -> 254 | CNS15: =CNS11/2 -> 5000

Sheet For SanKey Base
A1: PROJECT NAME | B1: AWARDED | C1: BRAND | D1: PRODUCT | E1: AGENCY | F1: CAMPAIGN | G1: VENDOR | H1: PHASE | I1: SUBMISSION | J1: BID NAME | K1: BIDFILE TYPE | L1: BID TOTAL | M1: BID TYPE | N1: AVERAGE BID | O1: DIVERSITY:: WOMAN DIRECTOR | P1: DIVERSITY:: MIINORITY DIRECTOR | Q1: DIVERSITY:: WOMAN EDITOR | R1: DIVERSITY:: MIINORITY EDITOR | S1: DIVERSITY:: WOMAN OWNED | T1: DIVERSITY:: MINORITY OWNED | U1: Women Work Pitched | V1: Women Work Awarded | W1: AvgBidPrice LUT.Average Bid Price
A2: Summer Fun | B2: 1 | C2: Kelly Hard Cider | D2: Kelly Summer Spritzer | E2: Korea SMB | F2: Q2 Summer Blitz | G2: Petulant Pictures | H2: Film & Video Production | I2: Summer Fun | J2: Petulant_SummerFun_LiveAction | K2: Original | L2: 960207.05 | M2: firm-bid | N2: 745866.47 | O2: 1 | U2: 960207.05 | V2: 960207.05 | W2: 745866.47
A3: Summer Fun | B3: 0 | C3: Kelly Hard Cider | D3: Kelly Summer Spritzer | E3: Korea SMB | F3: Q2 Summer Blitz | H3: Film & Video Production | I3: Summer Fun | J3: OpenFrameworks_SummerFun_LiveAction | K3: Original | L3: 662457.18 | M3: firm-bid | O3: 1 | P3: 1 | U3: 662457.18 | V3: 0 | W3: 745866.47
A4: Summer Fun | B4: 0 | C4: Kelly Hard Cider | D4: Kelly Summer Spritzer | E4: Korea SMB | F4: Q2 Summer Blitz | H4: Film & Video Production | I4: Summer Fun | J4: Club101_SummerFun_LiveAction | K4: Original | L4: 614935.17 | M4: firm-bid | U4: 0 | V4: 0 | W4: 745866.47
A5: Summer Fun | B5: 0 | C5: Kelly Hard Cider | D5: Kelly Summer Spritzer | E5: Korea SMB | F5: Q2 Summer Blitz | H5: Editorial | I5: Summer Fun | J5: ToTo_SummerFun_Edit | K5: Original | L5: 107610.42 | M5: firm-bid | U5: 0 | V5: 0 | W5: 109194.19
A6: Summer Fun | B6: 0 | C6: Kelly Hard Cider | D6: Kelly Summer Spritzer | E6: Korea SMB | F6: Q2 Summer Blitz | H6: Editorial | I6: Summer Fun | J6: MyrtleRow_SummerFun_Edit | K6: Original | L6: 133998.96 | M6: firm-bid | Q6: 1 | T6: 1 | U6: 0 | V6: 0 | W6: 109194.19
A7: Summer Fun | B7: 1 | C7: Kelly Hard Cider | D7: Kelly Summer Spritzer | E7: Korea SMB | F7: Q2 Summer Blitz | G7: Saks Street Edit | H7: Editorial | I7: Summer Fun | J7: SaksStreetEdit_SummerFun_Edit | K7: Original | L7: 85973.183 | M7: firm-bid | N7: 109194.19 | T7: 1 | U7: 0 | V7: 0 | W7: 109194.19
A8: Summer Fun | B8: 0 | C8: Kelly Hard Cider | D8: Kelly Summer Spritzer | E8: Korea SMB | F8: Q2 Summer Blitz | H8: Audio Post | I8: Audio Bid | J8: Audio Bid | K8: Original | L8: 14510 | M8: firm-bid | U8: 0 | V8: 0 | W8: 21656.667
A9: Summer Fun | B9: 1 | C9: Kelly Hard Cider | D9: Kelly Summer Spritzer | E9: Korea SMB | F9: Q2 Summer Blitz | G9: My Audio Fantasy | H9: Audio Post | I9: My Audio Fantasy | J9: AudioFantasybBid | K9: Original | L9: 21040 | M9: firm-bid | N9: 21656.667 | O9: 1 | R9: 1 | U9: 21040 | V9: 21040 | W9: 21656.667
A10: Summer Fun | B10: 0 | C10: Kelly Hard Cider | D10: Kelly Summer Spritzer | E10: Korea SMB | F10: Q2 Summer Blitz | H10: Audio Post | I10: Love Language"Summer Fun" | J10: Love124 | K10: Original | L10: 29420 | M10: firm-bid | U10: 0 | V10: 0 | W10: 21656.667
A11: Summer Fun | B11: 0 | C11: Kelly Hard Cider | D11: Kelly Summer Spritzer | E11: Korea SMB | F11: Q2 Summer Blitz | H11: Finishing | I11: colorMaven for Summer Fun v1 | J11: ColorMaven_SummerFun_Finishing | K11: Original | L11: 52850 | M11: firm-bid | S11: 1 | U11: 0 | V11: 0 | W11: 37833.333
A12: Summer Fun | B12: 0 | C12: Kelly Hard Cider | D12: Kelly Summer Spritzer | E12: Korea SMB | F12: Q2 Summer Blitz | H12: Finishing | I12: Andiamo for "Summer Fun" | J12: AndiamoImages_SummerFun_Finishing | K12: Original | L12: 20700 | M12: firm-bid | Q12: 1 | S12: 1 | U12: 0 | V12: 0 | W12: 37833.333
A13: Summer Fun | B13: 1 | C13: Kelly Hard Cider | D13: Kelly Summer Spritzer | E13: Korea SMB | F13: Q2 Summer Blitz | G13: Evan Bander LLC | H13: Finishing | I13: EB "Summer Fun" | J13: EvanBanderLLC_SummerFun_Finishing | K13: Original | L13: 39950 | M13: firm-bid | N13: 37833.333 | R13: 1 | T13: 1 | U13: 0 | V13: 0 | W13: 37833.333
A14: Summer Fun | B14: 1 | C14: Kelly Hard Cider | D14: Kelly Summer Spritzer | E14: Korea SMB | F14: Q2 Summer Blitz | G14: Petulant Pictures | H14: Sanitary Production Costs | I14: Summer Fun | J14: Petulant_SummerFun_Covid | K14: Original | L14: 4805.275 | M14: firm-bid | N14: 7050.3625 | O14: 1 | U14: 4805.275 | V14: 4805.275 | W14: 7050.3625
A15: Summer Fun | B15: 0 | C15: Kelly Hard Cider | D15: Kelly Summer Spritzer | E15: Korea SMB | F15: Q2 Summer Blitz | H15: Sanitary Production Costs | I15: Summer Fun | J15: OpenFrameworks_SummerFun_Covid | K15: Original | L15: 10043.812 | M15: firm-bid | O15: 1 | P15: 1 | U15: 10043.812 | V15: 0 | W15: 7050.3625
A16: Summer Fun | B16: 0 | C16: Kelly Hard Cider | D16: Kelly Summer Spritzer | E16: Korea SMB | F16: Q2 Summer Blitz | H16: Sanitary Production Costs | I16: Summer Fun | J16: Club101_SummerFun_Covid | K16: Original | L16: 6302 | M16: firm-bid | U16: 0 | V16: 0 | W16: 7050.3625
A17: Summer Fun | B17: 1 | C17: Kelly Hard Cider | D17: Kelly Summer Spritzer | E17: Korea SMB | F17: Q2 Summer Blitz | G17: Petulant Pictures | H17: Green Production Costs | I17: Summer Fun | J17: Petulant_SummerFun_Green | K17: Original | L17: 18176 | M17: firm-bid | N17: 14980 | O17: 1 | U17: 18176 | V17: 18176 | W17: 14980
A18: Summer Fun | B18: 0 | C18: Kelly Hard Cider | D18: Kelly Summer Spritzer | E18: Korea SMB | F18: Q2 Summer Blitz | H18: Green Production Costs | I18: Summer Fun | J18: OpenFrameworks_SummerFun_Green | K18: Original | L18: 14364 | M18: firm-bid | O18: 1 | P18: 1 | U18: 14364 | V18: 0 | W18: 14980
A19: Summer Fun | B19: 0 | C19: Kelly Hard Cider | D19: Kelly Summer Spritzer | E19: Korea SMB | F19: Q2 Summer Blitz | H19: Green Production Costs | I19: Summer Fun | J19: Club101_SummerFun_Green | K19: Original | L19: 12400 | M19: firm-bid | U19: 0 | V19: 0 | W19: 14980
A20: Summer Fun | B20: 0 | C20: Kelly Hard Cider | D20: Kelly Summer Spritzer | E20: Korea SMB | F20: Q2 Summer Blitz | H20: Photo Retouching & Post | I20: Kent Wilson Studio Estimate for "Summer Fun" #1 | J20: KentWilsonStudio_SummerFun_Retouching | K20: Original | L20: 39250 | M20: firm-bid | P20: 1 | U20: 0 | V20: 0 | W20: 37483.333
A21: Summer Fun | B21: 0 | C21: Kelly Hard Cider | D21: Kelly Summer Spritzer | E21: Korea SMB | F21: Q2 Summer Blitz | H21: Photo Retouching & Post | I21: Summer Fun | J21: Interstate_SummerFun_Retouching | K21: Original | L21: 36200 | M21: firm-bid | S21: 1 | U21: 0 | V21: 0 | W21: 37483.333
A22: Summer Fun | B22: 1 | C22: Kelly Hard Cider | D22: Kelly Summer Spritzer | E22: Korea SMB | F22: Q2 Summer Blitz | G22: Buck & Archie | H22: Photo Retouching & Post | I22: Buck & Archie "Kelly Hard Cider:Summer Fun" v2 | J22: BuckandArchie_SummerFun_Retouching | K22: Original | L22: 37000 | M22: firm-bid | N22: 37483.333 | U22: 0 | V22: 0 | W22: 37483.333
A23: Summer Fun | B23: 0 | C23: Kelly Hard Cider | D23: Kelly Summer Spritzer | E23: Korea SMB | F23: Q2 Summer Blitz | H23: Still Photography Production | I23: Kent Wilson Studio Estimate for "Summer Fun" #1 | J23: KentWilsonStudio_SummerFun_Stills | K23: Original | L23: 161541.3 | M23: firm-bid | P23: 1 | U23: 0 | V23: 0 | W23: 145472.98
A24: Summer Fun | B24: 0 | C24: Kelly Hard Cider | D24: Kelly Summer Spritzer | E24: Korea SMB | F24: Q2 Summer Blitz | H24: Still Photography Production | I24: Summer Fun | J24: Interstate_SummerFun_Stills | K24: Original | L24: 138331.55 | M24: firm-bid | S24: 1 | U24: 0 | V24: 0 | W24: 145472.98
A25: Summer Fun | B25: 1 | C25: Kelly Hard Cider | D25: Kelly Summer Spritzer | E25: Korea SMB | F25: Q2 Summer Blitz | G25: Buck & Archie | H25: Still Photography Production | I25: Buck & Archie "Kelly Hard Cider:Summer Fun" v2 | J25: BuckandArchie_SummerFun_Stills | K25: Original | L25: 136546.09 | M25: firm-bid | N25: 145472.98 | U25: 0 | V25: 0 | W25: 145472.98
A26: Summer Fun | B26: 0 | C26: Kelly Hard Cider | D26: Kelly Summer Spritzer | E26: Korea SMB | F26: Q2 Summer Blitz | H26: Music | I26: AEM "Kelly Summer Spritzer || Q2 Summer Blitz" | J26: ArnoldEstherMusic_SummerFun_Music | K26: Original | L26: 8700 | M26: firm-bid | U26: 0 | V26: 0 | W26: 38916.667
A27: Summer Fun | B27: 0 | C27: Kelly Hard Cider | D27: Kelly Summer Spritzer | E27: Korea SMB | F27: Q2 Summer Blitz | H27: Music | I27: "Summer Fun" - Special Oaks Music | J27: SpecialOaks_SummerFun_Music | K27: Original | L27: 69900 | M27: firm-bid | U27: 0 | V27: 0 | W27: 38916.667
A28: Summer Fun | B28: 1 | C28: Kelly Hard Cider | D28: Kelly Summer Spritzer | E28: Korea SMB | F28: Q2 Summer Blitz | G28: Tone & Logic | H28: Music | I28: T+L for "Kelly's Summer Fun" | J28: ToneandLogic_SummerFun_Music | K28: Original | L28: 38150 | M28: firm-bid | N28: 38916.667 | T28: 1 | U28: 0 | V28: 0 | W28: 38916.667
A29: The Traveller UK | B29: 0 | C29: Dewey North | D29: Dewey North 107º | E29: Last Station Group | F29: The Sophisticated Traveller | H29: Audio Post | I29: Special Oaks"The Traveller UK" | J29: Special Oaks | K29: Original | L29: 24800 | M29: firm-bid | O29: 1 | T29: 1 | U29: 24800 | V29: 0 | W29: 33935
A30: The Traveller UK | B30: 1 | C30: Dewey North | D30: Dewey North 107º | E30: Last Station Group | F30: The Sophisticated Traveller | G30: Love Language | H30: Audio Post | I30: Love Language "The Traveller UK" | J30: Love126 | K30: Original | L30: 43070 | M30: firm-bid | N30: 33935 | U30: 0 | V30: 0 | W30: 33935
A31: The Traveller UK | B31: 1 | C31: Dewey North | D31: Dewey North 107º | E31: Last Station Group | F31: The Sophisticated Traveller | G31: Love Language | H31: Music | I31: Love Language "The Traveller UK" - MUSIC ONLY | J31: LoveLanguage_TheTravellerUK_Music | K31: Original | L31: 20800 | M31: firm-bid | N31: 40150 | U31: 0 | V31: 0 | W31: 40150
A32: The Traveller UK | B32: 0 | C32: Dewey North | D32: Dewey North 107º | E32: Last Station Group | F32: The Sophisticated Traveller | H32: Music | I32: Frequency Presentation for "The Traveller UK" | J32: Frequency_TheTravellerUK_Music | K32: Original | L32: 49050 | M32: firm-bid | U32: 0 | V32: 0 | W32: 40150
A33: The Traveller UK | B33: 0 | C33: Dewey North | D33: Dewey North 107º | E33: Last Station Group | F33: The Sophisticated Traveller | H33: Music | I33: AEM "Dewey North || The Sophisticated Traveller (UK)" | J33: ArnoldEstherMusic_TheTravellerUK_Music | K33: Original | L33: 50600 | M33: firm-bid | U33: 0 | V33: 0 | W33: 40150
A34: The Traveller UK | B34: 1 | C34: Dewey North | D34: Dewey North 107º | E34: Last Station Group | F34: The Sophisticated Traveller | G34: EFX VFX | H34: VFX | I34: EFXvfx \\ "The Traveller UK" \\ v3 | J34: EFXVFX_TheTravellerUK_VFX | K34: Original | L34: 116454 | M34: firm-bid | N34: 104828.75 | U34: 0 | V34: 0 | W34: 104828.75
A35: The Traveller UK | B35: 0 | C35: Dewey North | D35: Dewey North 107º | E35: Last Station Group | F35: The Sophisticated Traveller | H35: VFX | I35: v2 - "The Traveller UK" //SORCERY | J35: Sorcery_TheTravellerUK_VFX | K35: Original | L35: 93203.5 | M35: firm-bid | U35: 0 | V35: 0 | W35: 104828.75
A36: The Traveller UK | B36: 0 | C36: Dewey North | D36: Dewey North 107º | E36: Last Station Group | F36: The Sophisticated Traveller | H36: Finishing | I36: colorMaven for "The Traveller UK" v3 | J36: ColorMaven_TheTravellerUK_Finishing | K36: Original | L36: 17500 | M36: firm-bid | S36: 1 | U36: 0 | V36: 0 | W36: 32250
A37: The Traveller UK | B37: 1 | C37: Dewey North | D37: Dewey North 107º | E37: Last Station Group | F37: The Sophisticated Traveller | G37: Andiamo Images | H37: Finishing | I37: Andiamo for "The Traveller" (UK Version) | J37: AndiamoImages_TheTravellerUK_Finishing | K37: Original | L37: 49250 | M37: firm-bid | N37: 32250 | O37: 1 | S37: 1 | U37: 49250 | V37: 49250 | W37: 32250
A38: The Traveller UK | B38: 0 | C38: Dewey North | D38: Dewey North 107º | E38: Last Station Group | F38: The Sophisticated Traveller | H38: Finishing | I38: ‚ÄúThe Traveller UK‚Äù - POI | J38: PersonsofInterest_TheTravellerUK_Finishing | K38: Original | L38: 30000 | M38: firm-bid | R38: 1 | U38: 0 | V38: 0 | W38: 32250
A39: The Traveller UK | B39: 1 | C39: Dewey North | D39: Dewey North 107º | E39: Last Station Group | F39: The Sophisticated Traveller | G39: Myrtle Row Editorial | H39: Editorial | I39: The Traveller UK | J39: MyrtleRow_TheTravellerUK_Edit | K39: Original | L39: 95889.792 | M39: firm-bid | N39: 93203.872 | T39: 1 | U39: 0 | V39: 0 | W39: 93203.872
A40: The Traveller UK | B40: 0 | C40: Dewey North | D40: Dewey North 107º | E40: Last Station Group | F40: The Sophisticated Traveller | H40: Editorial | I40: The Traveller UK | J40: TotalCuts_TheTravellerUK_Edit | K40: Original | L40: 67406.617 | M40: firm-bid | Q40: 1 | U40: 0 | V40: 0 | W40: 93203.872
...

Sheet Wmoen Creatives
A1: PHASE | B1: Awarded to Women | C1: UnAwarded Women | D1: PhaseTOtal
A2: Film & Video Production | B2: 960207.05 | C2: 0 | D2: 960207.05
A3: Film & Video Production | B3: 0 | C3: 662457.18 | D3: 662457.18
A4: Film & Video Production | B4: 0 | C4: 0 | D4: 55315214
A5: Editorial | B5: 0 | C5: 0 | D5: 8233052.3
A6: Editorial | B6: 0 | C6: 133998.96 | D6: 133998.96
A7: Audio Post | B7: 0 | C7: 0 | D7: 1663370
A8: Audio Post | B8: 21040 | C8: 0 | D8: 21040
A9: Finishing | B9: 0 | C9: 0 | D9: 1988950
A10: Finishing | B10: 0 | C10: 20700 | D10: 20700
A11: Sanitary Production Costs | B11: 4805.275 | C11: 0 | D11: 4805.275
A12: Sanitary Production Costs | B12: 0 | C12: 10043.812 | D12: 10043.812
A13: Sanitary Production Costs | B13: 0 | C13: 0 | D13: 481039.54
... A115: Photo Retouching & Post | B115: 0 | C115: 31950 | D115: 31950

Sheet RevWomCreat
A1: PROJECT NAME | B1: AWARDED | C1: BRAND | D1: PRODUCT | E1: AGENCY | F1: CAMPAIGN | G1: VENDOR | H1: PHASE | I1: SUBMISSION | J1: BID NAME | K1: BIDFILE TYPE | L1: BID TOTAL | M1: BID TYPE | N1: AVERAGE BID | O1: DIVERSITY:: WOMAN DIRECTOR | P1: DIVERSITY:: MIINORITY DIRECTOR | Q1: DIVERSITY:: WOMAN EDITOR | R1: DIVERSITY:: MIINORITY EDITOR | S1: DIVERSITY:: WOMAN OWNED | T1: DIVERSITY:: MINORITY OWNED | U1: Women Work Pitched | V1: Women Work Awarded | W1: AvgBidPrice LUT.Average Bid Price | X1: Total Award | Y1: All Awarded
A2: Summer Fun | B2: 1 | C2: Kelly Hard Cider | D2: Kelly Summer Spritzer | E2: Korea SMB | F2: Q2 Summer Blitz | G2: Petulant Pictures | H2: Film & Video Production | I2: Summer Fun | J2: Petulant_SummerFun_LiveAction | K2: Original | L2: 960207.05 | M2: firm-bid | N2: 745866.47 | O2: 1 | U2: 960207.05 | V2: 960207.05 | W2: 745866.47 | X2: 960207.05 | Y2: 960207.05
A3: Summer Fun | B3: 0 | C3: Kelly Hard Cider | D3: Kelly Summer Spritzer | E3: Korea SMB | F3: Q2 Summer Blitz | H3: Film & Video Production | I3: Summer Fun | J3: OpenFrameworks_SummerFun_LiveAction | K3: Original | L3: 662457.18 | M3: firm-bid | O3: 1 | P3: 1 | U3: 662457.18 | V3: 0 | W3: 745866.47
A4: Summer Fun | B4: 0 | C4: Kelly Hard Cider | D4: Kelly Summer Spritzer | E4: Korea SMB | F4: Q2 Summer Blitz | H4: Film & Video Production | I4: Summer Fun | J4: Club101_SummerFun_LiveAction | K4: Original | L4: 614935.17 | M4: firm-bid | U4: 0 | V4: 0 | W4: 745866.47
A5: Summer Fun | B5: 0 | C5: Kelly Hard Cider | D5: Kelly Summer Spritzer | E5: Korea SMB | F5: Q2 Summer Blitz | H5: Editorial | I5: Summer Fun | J5: ToTo_SummerFun_Edit | K5: Original | L5: 107610.42 | M5: firm-bid | U5: 0 | V5: 0 | W5: 109194.19
A6: Summer Fun | B6: 0 | C6: Kelly Hard Cider | D6: Kelly Summer Spritzer | E6: Korea SMB | F6: Q2 Summer Blitz | H6: Editorial | I6: Summer Fun | J6: MyrtleRow_SummerFun_Edit | K6: Original | L6: 133998.96 | M6: firm-bid | Q6: 1 | T6: 1 | U6: 0 | V6: 0 | W6: 109194.19
A7: Summer Fun | B7: 1 | C7: Kelly Hard Cider | D7: Kelly Summer Spritzer | E7: Korea SMB | F7: Q2 Summer Blitz | G7: Saks Street Edit | H7: Editorial | I7: Summer Fun | J7: SaksStreetEdit_SummerFun_Edit | K7: Original | L7: 85973.183 | M7: firm-bid | N7: 109194.19 | T7: 1 | U7: 0 | V7: 0 | W7: 109194.19 | X7: 85973.183 | Y7: 85973.183
A8: Summer Fun | B8: 0 | C8: Kelly Hard Cider | D8: Kelly Summer Spritzer | E8: Korea SMB | F8: Q2 Summer Blitz | H8: Audio Post | I8: Audio Bid | J8: Audio Bid | K8: Original | L8: 14510 | M8: firm-bid | U8: 0 | V8: 0 | W8: 21656.667
A9: Summer Fun | B9: 1 | C9: Kelly Hard Cider | D9: Kelly Summer Spritzer | E9: Korea SMB | F9: Q2 Summer Blitz | G9: My Audio Fantasy | H9: Audio Post | I9: My Audio Fantasy | J9: AudioFantasybBid | K9: Original | L9: 21040 | M9: firm-bid | N9: 21656.667 | O9: 1 | R9: 1 | U9: 21040 | V9: 21040 | W9: 21656.667 | X9: 21040 | Y9: 21040
A10: Summer Fun | B10: 0 | C10: Kelly Hard Cider | D10: Kelly Summer Spritzer | E10: Korea SMB | F10: Q2 Summer Blitz | H10: Audio Post | I10: Love Language"Summer Fun" | J10: Love124 | K10: Original | L10: 29420 | M10: firm-bid | U10: 0 | V10: 0 | W10: 21656.667
A11: Summer Fun | B11: 0 | C11: Kelly Hard Cider | D11: Kelly Summer Spritzer | E11: Korea SMB | F11: Q2 Summer Blitz | H11: Finishing | I11: colorMaven for Summer Fun v1 | J11: ColorMaven_SummerFun_Finishing | K11: Original | L11: 52850 | M11: firm-bid | S11: 1 | U11: 0 | V11: 0 | W11: 37833.333
A12: Summer Fun | B12: 0 | C12: Kelly Hard Cider | D12: Kelly Summer Spritzer | E12: Korea SMB | F12: Q2 Summer Blitz | H12: Finishing | I12: Andiamo for "Summer Fun" | J12: AndiamoImages_SummerFun_Finishing | K12: Original | L12: 20700 | M12: firm-bid | Q12: 1 | S12: 1 | U12: 0 | V12: 0 | W12: 37833.333
A13: Summer Fun | B13: 1 | C13: Kelly Hard Cider | D13: Kelly Summer Spritzer | E13: Korea SMB | F13: Q2 Summer Blitz | G13: Evan Bander LLC | H13: Finishing | I13: EB "Summer Fun" | J13: EvanBanderLLC_SummerFun_Finishing | K13: Original | L13: 39950 | M13: firm-bid | N13: 37833.333 | R13: 1 | T13: 1 | U13: 0 | V13: 0 | W13: 37833.333 | X13: 39950 | Y13: 39950
A14: Summer Fun | B14: 1 | C14: Kelly Hard Cider | D14: Kelly Summer Spritzer | E14: Korea SMB | F14: Q2 Summer Blitz | G14: Petulant Pictures | H14: Sanitary Production Costs | I14: Summer Fun | J14: Petulant_SummerFun_Covid | K14: Original | L14: 4805.275 | M14: firm-bid | N14: 7050.3625 | O14: 1 | U14: 4805.275 | V14: 4805.275 | W14: 7050.3625 | X14: 4805.275 | Y14: 4805.275
A15: Summer Fun | B15: 0 | C15: Kelly Hard Cider | D15: Kelly Summer Spritzer | E15: Korea SMB | F15: Q2 Summer Blitz | H15: Sanitary Production Costs | I15: Summer Fun | J15: OpenFrameworks_SummerFun_Covid | K15: Original | L15: 10043.812 | M15: firm-bid | O15: 1 | P15: 1 | U15: 10043.812 | V15: 0 | W15: 7050.3625
A16: Summer Fun | B16: 0 | C16: Kelly Hard Cider | D16: Kelly Summer Spritzer | E16: Korea SMB | F16: Q2 Summer Blitz | H16: Sanitary Production Costs | I16: Summer Fun | J16: Club101_SummerFun_Covid | K16: Original | L16: 6302 | M16: firm-bid | U16: 0 | V16: 0 | W16: 7050.3625
A17: Summer Fun | B17: 1 | C17: Kelly Hard Cider | D17: Kelly Summer Spritzer | E17: Korea SMB | F17: Q2 Summer Blitz | G17: Petulant Pictures | H17: Green Production Costs | I17: Summer Fun | J17: Petulant_SummerFun_Green | K17: Original | L17: 18176 | M17: firm-bid | N17: 14980 | O17: 1 | U17: 18176 | V17: 18176 | W17: 14980 | X17: 18176 | Y17: 18176
A18: Summer Fun | B18: 0 | C18: Kelly Hard Cider | D18: Kelly Summer Spritzer | E18: Korea SMB | F18: Q2 Summer Blitz | H18: Green Production Costs | I18: Summer Fun | J18: OpenFrameworks_SummerFun_Green | K18: Original | L18: 14364 | M18: firm-bid | O18: 1 | P18: 1 | U18: 14364 | V18: 0 | W18: 14980
A19: Summer Fun | B19: 0 | C19: Kelly Hard Cider | D19: Kelly Summer Spritzer | E19: Korea SMB | F19: Q2 Summer Blitz | H19: Green Production Costs | I19: Summer Fun | J19: Club101_SummerFun_Green | K19: Original | L19: 12400 | M19: firm-bid | U19: 0 | V19: 0 | W19: 14980
A20: Summer Fun | B20: 0 | C20: Kelly Hard Cider | D20: Kelly Summer Spritzer | E20: Korea SMB | F20: Q2 Summer Blitz | H20: Photo Retouching & Post | I20: Kent Wilson Studio Estimate for "Summer Fun" #1 | J20: KentWilsonStudio_SummerFun_Retouching | K20: Original | L20: 39250 | M20: firm-bid | P20: 1 | U20: 0 | V20: 0 | W20: 37483.333
A21: Summer Fun | B21: 0 | C21: Kelly Hard Cider | D21: Kelly Summer Spritzer | E21: Korea SMB | F21: Q2 Summer Blitz | H21: Photo Retouching & Post | I21: Summer Fun | J21: Interstate_SummerFun_Retouching | K21: Original | L21: 36200 | M21: firm-bid | S21: 1 | U21: 0 | V21: 0 | W21: 37483.333
A22: Summer Fun | B22: 1 | C22: Kelly Hard Cider | D22: Kelly Summer Spritzer | E22: Korea SMB | F22: Q2 Summer Blitz | G22: Buck & Archie | H22: Photo Retouching & Post | I22: Buck & Archie "Kelly Hard Cider:Summer Fun" v2 | J22: BuckandArchie_SummerFun_Retouching | K22: Original | L22: 37000 | M22: firm-bid | N22: 37483.333 | U22: 0 | V22: 0 | W22: 37483.333 | X22: 37000 | Y22: 37000
A23: Summer Fun | B23: 0 | C23: Kelly Hard Cider | D23: Kelly Summer Spritzer | E23: Korea SMB | F23: Q2 Summer Blitz | H23: Still Photography Production | I23: Kent Wilson Studio Estimate for "Summer Fun" #1 | J23: KentWilsonStudio_SummerFun_Stills | K23: Original | L23: 161541.3 | M23: firm-bid | P23: 1 | U23: 0 | V23: 0 | W23: 145472.98
A24: Summer Fun | B24: 0 | C24: Kelly Hard Cider | D24: Kelly Summer Spritzer | E24: Korea SMB | F24: Q2 Summer Blitz | H24: Still Photography Production | I24: Summer Fun | J24: Interstate_SummerFun_Stills | K24: Original | L24: 138331.55 | M24: firm-bid | S24: 1 | U24: 0 | V24: 0 | W24: 145472.98
A25: Summer Fun | B25: 1 | C25: Kelly Hard Cider | D25: Kelly Summer Spritzer | E25: Korea SMB | F25: Q2 Summer Blitz | G25: Buck & Archie | H25: Still Photography Production | I25: Buck & Archie "Kelly Hard Cider:Summer Fun" v2 | J25: BuckandArchie_SummerFun_Stills | K25: Original | L25: 136546.09 | M25: firm-bid | N25: 145472.98 | U25: 0 | V25: 0 | W25: 145472.98 | X25: 136546.09 | Y25: 136546.09
A26: Summer Fun | B26: 0 | C26: Kelly Hard Cider | D26: Kelly Summer Spritzer | E26: Korea SMB | F26: Q2 Summer Blitz | H26: Music | I26: AEM "Kelly Summer Spritzer || Q2 Summer Blitz" | J26: ArnoldEstherMusic_SummerFun_Music | K26: Original | L26: 8700 | M26: firm-bid | U26: 0 | V26: 0 | W26: 38916.667
A27: Summer Fun | B27: 0 | C27: Kelly Hard Cider | D27: Kelly Summer Spritzer | E27: Korea SMB | F27: Q2 Summer Blitz | H27: Music | I27: "Summer Fun" - Special Oaks Music | J27: SpecialOaks_SummerFun_Music | K27: Original | L27: 69900 | M27: firm-bid | U27: 0 | V27: 0 | W27: 38916.667
A28: Summer Fun | B28: 1 | C28: Kelly Hard Cider | D28: Kelly Summer Spritzer | E28: Korea SMB | F28: Q2 Summer Blitz | G28: Tone & Logic | H28: Music | I28: T+L for "Kelly's Summer Fun" | J28: ToneandLogic_SummerFun_Music | K28: Original | L28: 38150 | M28: firm-bid | N28: 38916.667 | T28: 1 | U28: 0 | V28: 0 | W28: 38916.667 | X28: 38150 | Y28: 38150
A29: The Traveller UK | B29: 0 | C29: Dewey North | D29: Dewey North 107º | E29: Last Station Group | F29: The Sophisticated Traveller | H29: Audio Post | I29: Special Oaks"The Traveller UK" | J29: Special Oaks | K29: Original | L29: 24800 | M29: firm-bid | O29: 1 | T29: 1 | U29: 24800 | V29: 0 | W29: 33935
A30: The Traveller UK | B30: 1 | C30: Dewey North | D30: Dewey North 107º | E30: Last Station Group | F30: The Sophisticated Traveller | G30: Love Language | H30: Audio Post | I30: Love Language "The Traveller UK" | J30: Love126 | K30: Original | L30: 43070 | M30: firm-bid | N30: 33935 | U30: 0 | V30: 0 | W30: 33935 | X30: 43070 | Y30: 43070
A31: The Traveller UK | B31: 1 | C31: Dewey North | D31: Dewey North 107º | E31: Last Station Group | F31: The Sophisticated Traveller | G31: Love Language | H31: Music | I31: Love Language "The Traveller UK" - MUSIC ONLY | J31: LoveLanguage_TheTravellerUK_Music | K31: Original | L31: 20800 | M31: firm-bid | N31: 40150 | U31: 0 | V31: 0 | W31: 40150 | X31: 20800 | Y31: 20800
A32: The Traveller UK | B32: 0 | C32: Dewey North | D32: Dewey North 107º | E32: Last Station Group | F32: The Sophisticated Traveller | H32: Music | I32: Frequency Presentation for "The Traveller UK" | J32: Frequency_TheTravellerUK_Music | K32: Original | L32: 49050 | M32: firm-bid | U32: 0 | V32: 0 | W32: 40150
A33: The Traveller UK | B33: 0 | C33: Dewey North | D33: Dewey North 107º | E33: Last Station Group | F33: The Sophisticated Traveller | H33: Music | I33: AEM "Dewey North || The Sophisticated Traveller (UK)" | J33: ArnoldEstherMusic_TheTravellerUK_Music | K33: Original | L33: 50600 | M33: firm-bid | U33: 0 | V33: 0 | W33: 40150
A34: The Traveller UK | B34: 1 | C34: Dewey North | D34: Dewey North 107º | E34: Last Station Group | F34: The Sophisticated Traveller | G34: EFX VFX | H34: VFX | I34: EFXvfx \\ "The Traveller UK" \\ v3 | J34: EFXVFX_TheTravellerUK_VFX | K34: Original | L34: 116454 | M34: firm-bid | N34: 104828.75 | U34: 0 | V34: 0 | W34: 104828.75 | X34: 116454 | Y34: 116454
A35: The Traveller UK | B35: 0 | C35: Dewey North | D35: Dewey North 107º | E35: Last Station Group | F35: The Sophisticated Traveller | H35: VFX | I35: v2 - "The Traveller UK" //SORCERY | J35: Sorcery_TheTravellerUK_VFX | K35: Original | L35: 93203.5 | M35: firm-bid | U35: 0 | V35: 0 | W35: 104828.75
A36: The Traveller UK | B36: 0 | C36: Dewey North | D36: Dewey North 107º | E36: Last Station Group | F36: The Sophisticated Traveller | H36: Finishing | I36: colorMaven for "The Traveller UK" v3 | J36: ColorMaven_TheTravellerUK_Finishing | K36: Original | L36: 17500 | M36: firm-bid | S36: 1 | U36: 0 | V36: 0 | W36: 32250
A37: The Traveller UK | B37: 1 | C37: Dewey North | D37: Dewey North 107º | E37: Last Station Group | F37: The Sophisticated Traveller | G37: Andiamo Images | H37: Finishing | I37: Andiamo for "The Traveller" (UK Version) | J37: AndiamoImages_TheTravellerUK_Finishing | K37: Original | L37: 49250 | M37: firm-bid | N37: 32250 | O37: 1 | S37: 1 | U37: 49250 | V37: 49250 | W37: 32250 | X37: 49250 | Y37: 49250
A38: The Traveller UK | B38: 0 | C38: Dewey North | D38: Dewey North 107º | E38: Last Station Group | F38: The Sophisticated Traveller | H38: Finishing | I38: ‚ÄúThe Traveller UK‚Äù - POI | J38: PersonsofInterest_TheTravellerUK_Finishing | K38: Original | L38: 30000 | M38: firm-bid | R38: 1 | U38: 0 | V38: 0 | W38: 32250
A39: The Traveller UK | B39: 1 | C39: Dewey North | D39: Dewey North 107º | E39: Last Station Group | F39: The Sophisticated Traveller | G39: Myrtle Row Editorial | H39: Editorial | I39: The Traveller UK | J39: MyrtleRow_TheTravellerUK_Edit | K39: Original | L39: 95889.792 | M39: firm-bid | N39: 93203.872 | T39: 1 | U39: 0 | V39: 0 | W39: 93203.872 | X39: 95889.792 | Y39: 95889.792
A40: The Traveller UK | B40: 0 | C40: Dewey North | D40: Dewey North 107º | E40: Last Station Group | F40: The Sophisticated Traveller | H40: Editorial | I40: The Traveller UK | J40: TotalCuts_TheTravellerUK_Edit | K40: Original | L40: 67406.617 | M40: firm-bid | Q40: 1 | U40: 0 | V40: 0 | W40: 93203.872
...

Sheet New Sankey
A1: Row Labels | B1: Sum of BID TOTAL | C1: Sum of Women Work Pitched | D1: Sum of Women Work Awarded | E1: Sum of Total Award | G1: Row Labels | H1: Sum of Women Work Pitched | I1: Sum of Women Work Awarded | K1: Agency | L1: Pitched | M1: Awarded
A2: Audio Post | B2: 2663120 | C2: 434880 | D2: 225190 | E2: 1127400 | G2: Aster PPK | H2: 2723028.5 | I2: 1002751 | K2: =G2 -> Aster PPK | L2: =H2 -> 2723028.5 | M2: =I2 -> 1002751
A3: Behind The Scenes (BTS) | B3: 335817.83 | C3: 74757.475 | D3: 36236.5 | E3: 124070.62 | G3: Cantor Asia Media | H3: 1746051.4 | I3: 833932.81 | K3: =G3 -> Cantor Asia Media | L3: =H3 -> 1746051.4 | M3: =I3 -> 833932.81
A4: Editorial | B4: 9593788.1 | C4: 0 | D4: 0 | E4: 3528420.8 | G4: Geoffrey Monty Allen | H4: 920570.16 | I4: 183460 | K4: =G4 -> Geoffrey Monty Allen | L4: =H4 -> 920570.16 | M4: =I4 -> 183460
A5: Film & Video Production | B5: 64143459 | C5: 8828244.8 | D5: 3126995.8 | E5: 23213713 | G5: Idea Manufacturing | H5: 0 | I5: 0 | K5: =G5 -> Idea Manufacturing | L5: =H5 -> 0 | M5: =I5 -> 0
A6: Finishing | B6: 2500550 | C6: 49250 | D6: 49250 | E6: 1107850 | G6: Korea SMB | H6: 1691093.3 | I6: 1004228.3 | K6: =G6 -> Korea SMB | L6: =H6 -> 1691093.3 | M6: =I6 -> 1004228.3
A7: Green Production Costs | B7: 825054 | C7: 140452 | D7: 51526 | E7: 295508 | G7: Last Station Group | H7: 1378028.8 | I7: 49250 | K7: =G7 -> Last Station Group | L7: =H7 -> 1378028.8 | M7: =I7 -> 49250
A8: Music | B8: 697000 | C8: 8600 | D8: 0 | E8: 231750 | G8: Top Notch Creative | H8: 1943021.8 | I8: 636924.79 | K8: =G8 -> Top Notch Creative | L8: =H8 -> 1943021.8 | M8: =I8 -> 636924.79
A9: Photo Retouching & Post | B9: 830150 | C9: 114250 | D9: 12500 | E9: 311500 | G9: Grand Total | H9: 10401794 | I9: 3710547
A10: Sanitary Production Costs | B10: 571764.71 | C10: 90725.167 | D10: 21025.048 | E10: 192053.45
A11: Still Photography Production | B11: 3693749.9 | C11: 660634.55 | D11: 187823.63 | E11: 1420184.1
A12: VFX | B12: 1429070.5 | C12: 0 | D12: 0 | E12: 575991
A13: Grand Total | B13: 87283524 | C13: 10401794 | D13: 3710547 | E13: 32128441
H18: All Work | I18: 10000
H19: Awarded | I19: 3000
H20: Women | I20: 254

Sheet Sheet8
A1: Source | B1: Target | C1: Value | D1: Type | F1: Source | G1: Target | H1: Value | I1: Type
A2: Edit | B2: Edit pitch men | C2: =GETPIVOTDATA("Sum of BID TOTAL",'New Sankey'!$A$1,"PHASE","Editorial")-GETPIVOTDATA("Sum of Women Work Pitched",'New Sankey'!$A$1,"PHASE","Editorial") -> 9593788.1 | D2: input | F2: Production Pitch men | G2: Total Pitched | H2: =GETPIVOTDATA("Sum of BID TOTAL",'New Sankey'!$A$1,"PHASE","Film & Video Production")-GETPIVOTDATA("Sum of Women Work Pitched",'New Sankey'!$A$1,"PHASE","Film & Video Production") -> 55315214 | I2: input
A3: Edit | B3: Edit pitch women | C3: =GETPIVOTDATA("Sum of Women Work Pitched",'New Sankey'!$A$1,"PHASE","Editorial") -> 0 | D3: input | F3: Production Pitch Women | G3: Total Pitched | H3: =GETPIVOTDATA("Sum of Women Work Pitched",'New Sankey'!$A$1,"PHASE","Film & Video Production") -> 8828244.8 | I3: input
A4: Production | B4: Production Pitch men | C4: =GETPIVOTDATA("Sum of BID TOTAL",'New Sankey'!$A$1,"PHASE","Film & Video Production")-GETPIVOTDATA("Sum of Women Work Pitched",'New Sankey'!$A$1,"PHASE","Film & Video Production") -> 55315214 | D4: profit | F4: Post Pitch Men | G4: Total Pitched | H4: =C2+C6+C8+C16+C10 -> 16390799 | I4: profit
A5: Production | B5: Production Pitch Women | C5: =GETPIVOTDATA("Sum of Women Work Pitched",'New Sankey'!$A$1,"PHASE","Film & Video Production") -> 8828244.8 | D5: profit | F5: Post Pitch Women | G5: Total Pitched | H5: =C3+C7+C9+C11+C17 -> 492730 | I5: profit
A6: Audio | B6: Audio Pitch Men | C6: =GETPIVOTDATA("Sum of BID TOTAL",'New Sankey'!$A$1,"PHASE","Audio Post")-GETPIVOTDATA("Sum of Women Work Pitched",'New Sankey'!$A$1,"PHASE","Audio Post") -> 2228240 | D6: equity | F6: Stills Pitch Men | G6: Total Pitched | H6: =C12 -> 3749015.4 | I6: equity
A7: Audio | B7: Audio Pitch Women | C7: =GETPIVOTDATA("Sum of Women Work Pitched",'New Sankey'!$A$1,"PHASE","Audio Post") -> 434880 | D7: equity | F7: Stills Pitch Women | G7: Total Pitched | H7: =C13 -> 774884.55 | I7: equity
A8: Finishing | B8: Finishing Pitch Men | C8: =GETPIVOTDATA("Sum of BID TOTAL",'New Sankey'!$A$1,"PHASE","Finishing")-GETPIVOTDATA("Sum of Women Work Pitched",'New Sankey'!$A$1,"PHASE","Finishing") -> 2451300 | D8: input | F8: BTS Pitch Men | G8: Total Pitched | H8: =C14 -> 261060.35 | I8: input | L8: Edit pitch men | M8: Pitched | N8: 200 | O8: input
A9: Finishing | B9: Finishing Pitch Women | C9: =GETPIVOTDATA("Sum of Women Work Pitched",'New Sankey'!$A$1,"PHASE","Finishing") -> 49250 | D9: input | F9: BTS Pitch Women | G9: Total Pitched | H9: =C15 -> 74757.475 | I9: input | L9: Edit pitch women | M9: Pitched | N9: 1000 | O9: input
A10: Music | B10: Music Pitch Men | C10: =GETPIVOTDATA("Sum of BID TOTAL",'New Sankey'!$A$1,"PHASE","Music")-GETPIVOTDATA("Sum of Women Work Pitched",'New Sankey'!$A$1,"PHASE","Music") -> 688400 | D10: profit | F10: Total Pitched | G10: Production award men | H10: =GETPIVOTDATA("Sum of Total Award",'New Sankey'!$A$1,"PHASE","Film & Video Production")-GETPIVOTDATA("Sum of Women Work Awarded",'New Sankey'!$A$1,"PHASE","Film & Video Production") -> 20086717 | I10: profit | L10: Production Pitch men | M10: Pitched | N10: 8000 | O10: profit
A11: Music | B11: Music Pitch Women | C11: =GETPIVOTDATA("Sum of Women Work Pitched",'New Sankey'!$A$1,"PHASE","Music") -> 8600 | D11: profit | F11: Total Pitched | G11: Production award Women | H11: =GETPIVOTDATA("Sum of Women Work Awarded",'New Sankey'!$A$1,"PHASE","Film & Video Production") -> 3126995.8 | I11: equity | L11: Production Pitch Women | M11: Pitched | N11: 2000 | O11: profit
A12: Stills | B12: Stills Pitch Men | C12: =GETPIVOTDATA("Sum of BID TOTAL",'New Sankey'!$A$1,"PHASE","Still Photography Production")+GETPIVOTDATA("Sum of BID TOTAL",'New Sankey'!$A$1,"PHASE","Photo Retouching & Post")-GETPIVOTDATA("Sum of Women Work Pitched",'New Sankey'!$A$1,"PHASE","Photo Retouching & Post")-GETPIVOTDATA("Sum of Women Work Pitched",'New Sankey'!$A$1,"PHASE","Still Photography Production") -> 3749015.4 | D12: equity | F12: Total Pitched | G12: Post award Men | H12: =C35+C39+C41+C43+C49 -> 6296971.8 | I12: profit | L12: Audio Pitch Men | M12: Pitched | N12: 1500 | O12: equity
A13: Stills | B13: Stills Pitch Women | C13: =GETPIVOTDATA("Sum of Women Work Pitched",'New Sankey'!$A$1,"PHASE","Photo Retouching & Post")+GETPIVOTDATA("Sum of Women Work Pitched",'New Sankey'!$A$1,"PHASE","Still Photography Production") -> 774884.55 | D13: equity | F13: Total Pitched | G13: Post award Women | H13: =C36+C40+C42+C44+C50 -> 274440 | I13: equity | L13: Audio Pitch Women | M13: Pitched | N13: 500 | O13: equity
A14: BTS | B14: BTS Pitch Men | C14: =GETPIVOTDATA("Sum of BID TOTAL",'New Sankey'!$A$1,"PHASE","Behind The Scenes (BTS)")-GETPIVOTDATA("Sum of Women Work Pitched",'New Sankey'!$A$1,"PHASE","Behind The Scenes (BTS)") -> 261060.35 | D14: input | F14: Total Pitched | G14: stills Award Men | H14: =C45 -> 1531360.4 | I14: profit | L14: Pitched | M14: Edit Award men | N14: 1500 | O14: input
A15: BTS | B15: BTS Pitch Women | C15: =GETPIVOTDATA("Sum of Women Work Pitched",'New Sankey'!$A$1,"PHASE","Behind The Scenes (BTS)") -> 74757.475 | D15: input | F15: Total Pitched | G15: Stills AwardWomen | H15: =C46 -> 200323.63 | I15: equity | L15: Pitched | M15: Edit Award women | N15: 500 | O15: input
A16: VFX | B16: VFX Pitch Men | C16: =GETPIVOTDATA("Sum of BID TOTAL",'New Sankey'!$A$1,"PHASE","VFX")-GETPIVOTDATA("Sum of Women Work Pitched",'New Sankey'!$A$1,"PHASE","VFX") -> 1429070.5 | D16: profit | F16: Total Pitched | G16: BTS Award Men | H16: =C47 -> 87834.125 | I16: profit | L16: Pitched | M16: Production Award men | N16: 3000 | O16: profit
A17: VFX | B17: VFX Pitch Women | C17: =GETPIVOTDATA("Sum of Women Work Pitched",'New Sankey'!$A$1,"PHASE","VFX") -> 0 | D17: profit | F17: Total Pitched | G17: Bts Award Women | H17: =C48 -> 36236.5 | I17: equity | L17: Pitched | M17: Production Award Women | N17: 1000 | O17: profit
A18: Edit pitch men | B18: Pitched | C18: =GETPIVOTDATA("Sum of BID TOTAL",'New Sankey'!$A$1,"PHASE","Editorial")-GETPIVOTDATA("Sum of Women Work Pitched",'New Sankey'!$A$1,"PHASE","Editorial") -> 9593788.1 | D18: input | I18: equity | L18: Pitched | M18: Audio Award Men | N18: 800 | O18: equity
A19: Edit pitch women | B19: Pitched | C19: =GETPIVOTDATA("Sum of Women Work Pitched",'New Sankey'!$A$1,"PHASE","Editorial") -> 0 | D19: input | I19: equity | L19: Pitched | M19: Audio Award Women | N19: 200 | O19: equity | P19: Award
A20: Production Pitch men | B20: Pitched | C20: =GETPIVOTDATA("Sum of BID TOTAL",'New Sankey'!$A$1,"PHASE","Film & Video Production")-GETPIVOTDATA("Sum of Women Work Pitched",'New Sankey'!$A$1,"PHASE","Film & Video Production") -> 55315214 | D20: profit | I20: input | P20: Award
A21: Production Pitch Women | B21: Pitched | C21: =GETPIVOTDATA("Sum of Women Work Pitched",'New Sankey'!$A$1,"PHASE","Film & Video Production") -> 8828244.8 | D21: profit | I21: input | P21: Award
A22: Audio Pitch Men | B22: Pitched | C22: =GETPIVOTDATA("Sum of BID TOTAL",'New Sankey'!$A$1,"PHASE","Audio Post")-GETPIVOTDATA("Sum of Women Work Pitched",'New Sankey'!$A$1,"PHASE","Audio Post") -> 2228240 | D22: equity | I22: profit | P22: Award
A23: Audio Pitch Women | B23: Pitched | C23: =GETPIVOTDATA("Sum of Women Work Pitched",'New Sankey'!$A$1,"PHASE","Audio Post") -> 434880 | D23: equity | I23: profit | P23: Award
A24: Finishing Pitch Men | B24: Pitched | C24: =GETPIVOTDATA("Sum of BID TOTAL",'New Sankey'!$A$1,"PHASE","Finishing")-GETPIVOTDATA("Sum of Women Work Pitched",'New Sankey'!$A$1,"PHASE","Finishing") -> 2451300 | D24: input | I24: equity | P24: Award
A25: Finishing Pitch Women | B25: Pitched | C25: =GETPIVOTDATA("Sum of Women Work Pitched",'New Sankey'!$A$1,"PHASE","Finishing") -> 49250 | D25: input | I25: equity | P25: Award
A26: Music Pitch Men | B26: Pitched | C26: =GETPIVOTDATA("Sum of BID TOTAL",'New Sankey'!$A$1,"PHASE","Music")-GETPIVOTDATA("Sum of Women Work Pitched",'New Sankey'!$A$1,"PHASE","Music") -> 688400 | D26: profit | P26: Award
A27: Music Pitch Women | B27: Pitched | C27: =GETPIVOTDATA("Sum of Women Work Pitched",'New Sankey'!$A$1,"PHASE","Music") -> 8600 | D27: profit | G27: Pitched Work | H27: =SUM(H1:H8) -> 85811947 | I27: Input
A28: Stills Pitch Men | B28: Pitched | C28: =GETPIVOTDATA("Sum of BID TOTAL",'New Sankey'!$A$1,"PHASE","Still Photography Production")+GETPIVOTDATA("Sum of BID TOTAL",'New Sankey'!$A$1,"PHASE","Photo Retouching & Post")-GETPIVOTDATA("Sum of Women Work Pitched",'New Sankey'!$A$1,"PHASE","Photo Retouching & Post")-GETPIVOTDATA("Sum of Women Work Pitched",'New Sankey'!$A$1,"PHASE","Still Photography Production") -> 3749015.4 | D28: equity | F28: Pitched Work | G28: Awarded Work | H28: =N41+N42 -> 31640880 | I28: Input | L28: Production | M28: Production Pitch men | N28: =GETPIVOTDATA("Sum of BID TOTAL",'New Sankey'!$A$1,"PHASE","Film & Video Production")-GETPIVOTDATA("Sum of Women Work Pitched",'New Sankey'!$A$1,"PHASE","Film & Video Production") -> 55315214 | O28: profit
A29: Stills Pitch Women | B29: Pitched | C29: =GETPIVOTDATA("Sum of Women Work Pitched",'New Sankey'!$A$1,"PHASE","Photo Retouching & Post")+GETPIVOTDATA("Sum of Women Work Pitched",'New Sankey'!$A$1,"PHASE","Still Photography Production") -> 774884.55 | D29: equity | F29: Awarded Work | G29: Awarded Production | H29: =H33+H34 -> 23213713 | I29: Cost | L29: Production | M29: Production Pitch Women | N29: =GETPIVOTDATA("Sum of Women Work Pitched",'New Sankey'!$A$1,"PHASE","Film & Video Production") -> 8828244.8 | O29: profit
A30: BTS Pitch Men | B30: Pitched | C30: =GETPIVOTDATA("Sum of BID TOTAL",'New Sankey'!$A$1,"PHASE","Behind The Scenes (BTS)")-GETPIVOTDATA("Sum of Women Work Pitched",'New Sankey'!$A$1,"PHASE","Behind The Scenes (BTS)") -> 261060.35 | D30: input | F30: Awarded Work | G30: Awarded Post | H30: =H35+H36 -> 6571411.8 | I30: Investment | L30: Post | M30: Post Pitch Men | N30: =C2+C6+C8+C16+C10 -> 16390799 | O30: equity
A31: BTS Pitch Women | B31: Pitched | C31: =GETPIVOTDATA("Sum of Women Work Pitched",'New Sankey'!$A$1,"PHASE","Behind The Scenes (BTS)") -> 74757.475 | D31: input | F31: Awarded Work | G31: Awarded Stills | H31: =H37+H38 -> 1731684.1 | I31: Cost | L31: Post | M31: Post Pitch Women | N31: =C3+C7+C9+C11+C17 -> 492730 | O31: equity
A32: VFX Pitch Men | B32: Pitched | C32: =GETPIVOTDATA("Sum of BID TOTAL",'New Sankey'!$A$1,"PHASE","VFX")-GETPIVOTDATA("Sum of Women Work Pitched",'New Sankey'!$A$1,"PHASE","VFX") -> 1429070.5 | D32: profit | F32: Awarded Work | G32: Awarded BTS | H32: =H39+H40 -> 124070.62 | I32: Investment | L32: Stills | M32: Stills Pitch Men | N32: =C12 -> 3749015.4 | O32: input
A33: VFX Pitch Women | B33: Pitched | C33: =GETPIVOTDATA("Sum of Women Work Pitched",'New Sankey'!$A$1,"PHASE","VFX") -> 0 | D33: profit | F33: Awarded Production | G33: Production Awarded to Men | H33: =H10 -> 20086717 | I33: Profit | L33: Stills | M33: Stills Pitch Women | N33: =C13 -> 774884.55 | O33: input
A34: Pitched | B34: Award | C34: =GETPIVOTDATA("Sum of Total Award",'New Sankey'!$A$1) -> 32128441 | D34: Profit | F34: Awarded Production | G34: Production Awarded to Women | H34: =H11 -> 3126995.8 | I34: Equity | L34: BTS | M34: BTS Pitch Men | N34: =C14 -> 261060.35 | O34: profit
A35: Award | B35: Edit award men | C35: =GETPIVOTDATA("Sum of Total Award",'New Sankey'!$A$1,"PHASE","Editorial")-GETPIVOTDATA("Sum of Women Work Awarded",'New Sankey'!$A$1,"PHASE","Editorial") -> 3528420.8 | D35: input | F35: Awarded Post | G35: Post Awarded to Men | H35: =H12 -> 6296971.8 | I35: Profit | L35: BTS | M35: BTS Pitch Women | N35: =C15 -> 74757.475 | O35: profit
A36: Award | B36: Edit award women | C36: =GETPIVOTDATA("Sum of Women Work Awarded",'New Sankey'!$A$1,"PHASE","Editorial") -> 0 | D36: input | F36: Awarded Post | G36: Post Awrded to Women | H36: =H13 -> 274440 | I36: Equity
A37: Award | B37: Production award men | C37: =GETPIVOTDATA("Sum of Total Award",'New Sankey'!$A$1,"PHASE","Film & Video Production")-GETPIVOTDATA("Sum of Women Work Awarded",'New Sankey'!$A$1,"PHASE","Film & Video Production") -> 20086717 | D37: profit | F37: Awarded Stills | G37: Stills Awarded to Men | H37: =H14 -> 1531360.4 | I37: Profit
A38: Award | B38: Production award Women | C38: =GETPIVOTDATA("Sum of Women Work Awarded",'New Sankey'!$A$1,"PHASE","Film & Video Production") -> 3126995.8 | D38: profit | F38: Awarded Stills | G38: Stills Awarded to Women | H38: =H15 -> 200323.63 | I38: Equity
A39: Award | B39: Audio award Men | C39: =GETPIVOTDATA("Sum of Total Award",'New Sankey'!$A$1,"PHASE","Audio Post")-GETPIVOTDATA("Sum of Women Work Awarded",'New Sankey'!$A$1,"PHASE","Audio Post") -> 902210 | D39: Profit | F39: Awarded BTS | G39: BTS Awarded to Men | H39: =H16 -> 87834.125 | I39: Profit
A40: Award | B40: Audio award Women | C40: =GETPIVOTDATA("Sum of Women Work Awarded",'New Sankey'!$A$1,"PHASE","Audio Post") -> 225190 | F40: Awarded BTS | G40: BTS Awarded to Women | H40: =H17 -> 36236.5 | I40: Equity
...

Sheet Sheet10

Sheet RevWomCreat (2)
A1: PROJECT NAME | B1: AWARDED | C1: BRAND | D1: PRODUCT | E1: AGENCY | F1: CAMPAIGN | G1: VENDOR | H1: PHASE | I1: SUBMISSION | J1: BID NAME | K1: BIDFILE TYPE | L1: BID TOTAL | M1: BID TYPE | N1: AVERAGE BID | O1: DIVERSITY:: WOMAN DIRECTOR | P1: DIVERSITY:: MIINORITY DIRECTOR | Q1: DIVERSITY:: WOMAN EDITOR | R1: DIVERSITY:: MIINORITY EDITOR | S1: DIVERSITY:: WOMAN OWNED | T1: DIVERSITY:: MINORITY OWNED | U1: Women Work Pitched | V1: Women Work Awarded | W1: AvgBidPrice LUT.Average Bid Price | X1: Total Award | Y1: All Awarded
A2: Summer Fun | B2: 1 | C2: Kelly Hard Cider | D2: Kelly Summer Spritzer | E2: Korea SMB | F2: Q2 Summer Blitz | G2: Petulant Pictures | H2: Film & Video Production | I2: Summer Fun | J2: Petulant_SummerFun_LiveAction | K2: Original | L2: 960207.05 | M2: firm-bid | N2: 745866.47 | O2: 1 | U2: 960207.05 | V2: 960207.05 | W2: 745866.47 | X2: 960207.05 | Y2: 960207.05
A3: Summer Fun | B3: 0 | C3: Kelly Hard Cider | D3: Kelly Summer Spritzer | E3: Korea SMB | F3: Q2 Summer Blitz | H3: Film & Video Production | I3: Summer Fun | J3: OpenFrameworks_SummerFun_LiveAction | K3: Original | L3: 662457.18 | M3: firm-bid | O3: 1 | P3: 1 | U3: 662457.18 | V3: 0 | W3: 745866.47
A4: Summer Fun | B4: 0 | C4: Kelly Hard Cider | D4: Kelly Summer Spritzer | E4: Korea SMB | F4: Q2 Summer Blitz | H4: Film & Video Production | I4: Summer Fun | J4: Club101_SummerFun_LiveAction | K4: Original | L4: 614935.17 | M4: firm-bid | U4: 0 | V4: 0 | W4: 745866.47
A5: Summer Fun | B5: 0 | C5: Kelly Hard Cider | D5: Kelly Summer Spritzer | E5: Korea SMB | F5: Q2 Summer Blitz | H5: Editorial | I5: Summer Fun | J5: ToTo_SummerFun_Edit | K5: Original | L5: 107610.42 | M5: firm-bid | U5: 0 | V5: 0 | W5: 109194.19
A6: Summer Fun | B6: 0 | C6: Kelly Hard Cider | D6: Kelly Summer Spritzer | E6: Korea SMB | F6: Q2 Summer Blitz | H6: Editorial | I6: Summer Fun | J6: MyrtleRow_SummerFun_Edit | K6: Original | L6: 133998.96 | M6: firm-bid | Q6: 1 | T6: 1 | U6: 0 | V6: 0 | W6: 109194.19
A7: Summer Fun | B7: 1 | C7: Kelly Hard Cider | D7: Kelly Summer Spritzer | E7: Korea SMB | F7: Q2 Summer Blitz | G7: Saks Street Edit | H7: Editorial | I7: Summer Fun | J7: SaksStreetEdit_SummerFun_Edit | K7: Original | L7: 85973.183 | M7: firm-bid | N7: 109194.19 | T7: 1 | U7: 0 | V7: 0 | W7: 109194.19 | X7: 85973.183 | Y7: 85973.183
A8: Summer Fun | B8: 0 | C8: Kelly Hard Cider | D8: Kelly Summer Spritzer | E8: Korea SMB | F8: Q2 Summer Blitz | H8: Audio Post | I8: Audio Bid | J8: Audio Bid | K8: Original | L8: 14510 | M8: firm-bid | U8: 0 | V8: 0 | W8: 21656.667
A9: Summer Fun | B9: 1 | C9: Kelly Hard Cider | D9: Kelly Summer Spritzer | E9: Korea SMB | F9: Q2 Summer Blitz | G9: My Audio Fantasy | H9: Audio Post | I9: My Audio Fantasy | J9: AudioFantasybBid | K9: Original | L9: 21040 | M9: firm-bid | N9: 21656.667 | O9: 1 | R9: 1 | U9: 21040 | V9: 21040 | W9: 21656.667 | X9: 21040 | Y9: 21040
A10: Summer Fun | B10: 0 | C10: Kelly Hard Cider | D10: Kelly Summer Spritzer | E10: Korea SMB | F10: Q2 Summer Blitz | H10: Audio Post | I10: Love Language"Summer Fun" | J10: Love124 | K10: Original | L10: 29420 | M10: firm-bid | U10: 0 | V10: 0 | W10: 21656.667
A11: Summer Fun | B11: 0 | C11: Kelly Hard Cider | D11: Kelly Summer Spritzer | E11: Korea SMB | F11: Q2 Summer Blitz | H11: Finishing | I11: colorMaven for Summer Fun v1 | J11: ColorMaven_SummerFun_Finishing | K11: Original | L11: 52850 | M11: firm-bid | S11: 1 | U11: 0 | V11: 0 | W11: 37833.333
A12: Summer Fun | B12: 0 | C12: Kelly Hard Cider | D12: Kelly Summer Spritzer | E12: Korea SMB | F12: Q2 Summer Blitz | H12: Finishing | I12: Andiamo for "Summer Fun" | J12: AndiamoImages_SummerFun_Finishing | K12: Original | L12: 20700 | M12: firm-bid | Q12: 1 | S12: 1 | U12: 0 | V12: 0 | W12: 37833.333
A13: Summer Fun | B13: 1 | C13: Kelly Hard Cider | D13: Kelly Summer Spritzer | E13: Korea SMB | F13: Q2 Summer Blitz | G13: Evan Bander LLC | H13: Finishing | I13: EB "Summer Fun" | J13: EvanBanderLLC_SummerFun_Finishing | K13: Original | L13: 39950 | M13: firm-bid | N13: 37833.333 | R13: 1 | T13: 1 | U13: 0 | V13: 0 | W13: 37833.333 | X13: 39950 | Y13: 39950
A14: Summer Fun | B14: 1 | C14: Kelly Hard Cider | D14: Kelly Summer Spritzer | E14: Korea SMB | F14: Q2 Summer Blitz | G14: Petulant Pictures | H14: Sanitary Production Costs | I14: Summer Fun | J14: Petulant_SummerFun_Covid | K14: Original | L14: 4805.275 | M14: firm-bid | N14: 7050.3625 | O14: 1 | U14: 4805.275 | V14: 4805.275 | W14: 7050.3625 | X14: 4805.275 | Y14: 4805.275
A15: Summer Fun | B15: 0 | C15: Kelly Hard Cider | D15: Kelly Summer Spritzer | E15: Korea SMB | F15: Q2 Summer Blitz | H15: Sanitary Production Costs | I15: Summer Fun | J15: OpenFrameworks_SummerFun_Covid | K15: Original | L15: 10043.812 | M15: firm-bid | O15: 1 | P15: 1 | U15: 10043.812 | V15: 0 | W15: 7050.3625
A16: Summer Fun | B16: 0 | C16: Kelly Hard Cider | D16: Kelly Summer Spritzer | E16: Korea SMB | F16: Q2 Summer Blitz | H16: Sanitary Production Costs | I16: Summer Fun | J16: Club101_SummerFun_Covid | K16: Original | L16: 6302 | M16: firm-bid | U16: 0 | V16: 0 | W16: 7050.3625
A17: Summer Fun | B17: 1 | C17: Kelly Hard Cider | D17: Kelly Summer Spritzer | E17: Korea SMB | F17: Q2 Summer Blitz | G17: Petulant Pictures | H17: Green Production Costs | I17: Summer Fun | J17: Petulant_SummerFun_Green | K17: Original | L17: 18176 | M17: firm-bid | N17: 14980 | O17: 1 | U17: 18176 | V17: 18176 | W17: 14980 | X17: 18176 | Y17: 18176
A18: Summer Fun | B18: 0 | C18: Kelly Hard Cider | D18: Kelly Summer Spritzer | E18: Korea SMB | F18: Q2 Summer Blitz | H18: Green Production Costs | I18: Summer Fun | J18: OpenFrameworks_SummerFun_Green | K18: Original | L18: 14364 | M18: firm-bid | O18: 1 | P18: 1 | U18: 14364 | V18: 0 | W18: 14980
A19: Summer Fun | B19: 0 | C19: Kelly Hard Cider | D19: Kelly Summer Spritzer | E19: Korea SMB | F19: Q2 Summer Blitz | H19: Green Production Costs | I19: Summer Fun | J19: Club101_SummerFun_Green | K19: Original | L19: 12400 | M19: firm-bid | U19: 0 | V19: 0 | W19: 14980
A20: Summer Fun | B20: 0 | C20: Kelly Hard Cider | D20: Kelly Summer Spritzer | E20: Korea SMB | F20: Q2 Summer Blitz | H20: Photo Retouching & Post | I20: Kent Wilson Studio Estimate for "Summer Fun" #1 | J20: KentWilsonStudio_SummerFun_Retouching | K20: Original | L20: 39250 | M20: firm-bid | P20: 1 | U20: 0 | V20: 0 | W20: 37483.333
A21: Summer Fun | B21: 0 | C21: Kelly Hard Cider | D21: Kelly Summer Spritzer | E21: Korea SMB | F21: Q2 Summer Blitz | H21: Photo Retouching & Post | I21: Summer Fun | J21: Interstate_SummerFun_Retouching | K21: Original | L21: 36200 | M21: firm-bid | S21: 1 | U21: 0 | V21: 0 | W21: 37483.333
